Workbook

Sheet  Compliance Radar
A1: Compliance Radar · AI under regulation
A2: Select your client's jurisdiction and the kit automatically displays the applicable rules, obligations, penalties, and recommended standards.
A5: JURISDICTION: | B5: Mexico
A7: Region: | B7: =VLOOKUP($B$5,'Tabla Maestra'!$A$5:$V$16,2,FALSE()) -> Latam
A8: Data protection authority: | B8: =VLOOKUP($B$5,'Tabla Maestra'!$A$5:$V$16,5,FALSE()) -> INAI
A10: 1. APPLICABLE LEGAL FRAMEWORK
A11: Main data protection standard: | B11: =VLOOKUP($B$5,'Tabla Maestra'!$A$5:$V$16,3,FALSE()) -> LFPDPPP
A12: Year of validity: | B12: =VLOOKUP($B$5,'Tabla Maestra'!$A$5:$V$16,4,FALSE()) -> 2010 (2024 reform in progress)
A13: EU AI Act extraterritorial: | B13: =VLOOKUP($B$5,'Tabla Maestra'!$A$5:$V$16,13,FALSE()) -> Yes, if you process EU data or sell to the EU
A14: AI Specific Framework (Local): | B14: =VLOOKUP($B$5,'Tabla Maestra'!$A$5:$V$16,20,FALSE()) -> Under legislative discussion
A16: 2. KEY OBLIGATIONS FOR DOING AI
A17: DPIA / PIA (Impact Assessment): | B17: =VLOOKUP($B$5,'Tabla Maestra'!$A$5:$V$16,6,FALSE()) -> Recommended (not explicitly required)
A18: Explicit consent: | B18: =VLOOKUP($B$5,'Tabla Maestra'!$A$5:$V$16,7,FALSE()) -> Yes, in most cases
A19: Right to an explanation of automated decisions: | B19: =VLOOKUP($B$5,'Tabla Maestra'!$A$5:$V$16,8,FALSE()) -> Partial
A20: Gap notification: | B20: =VLOOKUP($B$5,'Tabla Maestra'!$A$5:$V$16,9,FALSE()) -> Immediate (without a specific legal deadline)
A21: Mandatory DPO: | B21: =VLOOKUP($B$5,'Tabla Maestra'!$A$5:$V$16,10,FALSE()) -> Not generally; yes, large volumes.
A22: International transfers: | B22: =VLOOKUP($B$5,'Tabla Maestra'!$A$5:$V$16,11,FALSE()) -> Permitted with consent or clauses
A24: 3. MAXIMUM PENALTIES
A25: Maximum penalty: | B25: =VLOOKUP($B$5,'Tabla Maestra'!$A$5:$V$16,12,FALSE()) -> Up to 320,000 days of minimum wage (~USD 100K-110K)
A27: 4. RECOMMENDED STANDARDS AND FRAMEWORKS
A28: Standard / Frame | B28: Applicability | C28: Focus
A29: ISO/IEC 27001—Information Security | B29: =VLOOKUP($B$5,'Tabla Maestra'!$A$5:$V$16,14,FALSE()) -> Highly recommended | C29: Information security, the foundation of any serious program.
A30: ISO/IEC 27701 — Privacy Information Management | B30: =VLOOKUP($B$5,'Tabla Maestra'!$A$5:$V$16,15,FALSE()) -> Recommended | C30: Extension of ISO 27001 with privacy controls. Criticism regarding personal data.
A31: ISO/IEC 42001—AI Management System | B31: =VLOOKUP($B$5,'Tabla Maestra'!$A$5:$V$16,16,FALSE()) -> Recommended | C31: AI management system, certifiable. Key emerging standard.
A32: ISO/IEC 23894 — AI Risk Management | B32: =VLOOKUP($B$5,'Tabla Maestra'!$A$5:$V$16,17,FALSE()) -> Recommended | C32: AI risk management operational framework.
A33: NIST AI Risk Management Framework | B33: =VLOOKUP($B$5,'Tabla Maestra'!$A$5:$V$16,18,FALSE()) -> Reference | C33: US Voluntary Framework — widely adopted international reference.
A34: NIST Cybersecurity Framework (CSF) | B34: =VLOOKUP($B$5,'Tabla Maestra'!$A$5:$V$16,19,FALSE()) -> Reference | C34: Cybersecurity framework — de facto standard in the U.S.
A36: 5. SECTORAL AND SPECIFIC NOTES
A37: Typical sectoral regulators: | B37: =VLOOKUP($B$5,'Tabla Maestra'!$A$5:$V$16,21,FALSE()) -> CONDUSEF (finance), COFEPRIS (health), CNBV
A38: Specific notes: | B38: =VLOOKUP($B$5,'Tabla Maestra'!$A$5:$V$16,22,FALSE()) -> The 2024 reform brings Mexico closer to international standards. Greater focus on transfers and the rights of the data subject.
A41: 6. OPERATIONAL COMPLIANCE CHECKLIST FOR YOUR AI INITIATIVE
A42: Mark the current status of each control. High-risk systems under the EU AI Act and many local regulations require most of these controls.
A43: Control | B43: State | C43: Comments
A44: Updated inventory of AI systems in use or under development
A45: DPIA / PIA performed for each system with personal data
A46: Documented legal bases for processing
A47: Acceptable Use Policy for AI approved and communicated
A48: Model cards or technical documentation by system
A49: Right to explanation mechanisms implemented
A50: Documented gap notification procedure
...

Sheet  Catalog
A1: Catalog of use cases · AI in Legal and Compliance
A2: AI use cases applicable to the legal and compliance area. Mark in the last column those that apply to your organization.
A4: # | B4: Use case | C4: Description | D4: AI Family | E4: Typical KPI | F4: Required data | G4: Effort | H4: Maturity (1-5) | I4: Compliance / Risk | J4: Does this apply to us? | K4: Grades
A5: 1 | B5: Automatic contract review | C5: Identify risk clauses, deviations from the standard, and missing terms in incoming contracts. | D5: GenAI | E5: Review time, review coverage, risks detected | F5: Master templates, history of signed contracts, risk criteria | G5: Medium | H5: 5 | I5: Confidentiality; version traceability; mandatory human review.
A6: 2 | B6: Generating standard contract drafts | C6: Auto-generates NDAs, MSAs, SOWs, DPAs from templates and case parameters. | D6: GenAI | E6: Time to first draft, consistency, legal productivity | F6: Master templates, case parameters, counterparty data | G6: Quick Win | H6: 5 | I6: Human approval before submission; version control.
A7: 3 | B7: Contract comparison and redlining | C7: Compare the counterpart's proposal with the master template and suggest changes. | D7: GenAI | E7: Redlining time, identified risks, quality of changes | F7: Master template, counterparty contract | G7: Quick Win | H7: 4 | I7: Final decision of the lawyer; traceability of comments.
A8: 4 | B8: DPIA / PIA assisted | C8: Automatically generates a draft privacy impact assessment for initiatives involving personal data. | D8: GenAI | E8: DPIA processing time, completeness, traceability | F8: Project description, data involved, DPIA template | G8: Medium | H8: 4 | I8: DPO validation; mandatory human review; regulatory traceability.
A9: 5 | B9: Regulatory change tracking | C9: It monitors official publications and alerts about regulatory changes relevant to the client. | D9: ML / GenAI | E9: Regulatory coverage, detection time, false positives | F9: Official regulatory sources, taxonomy of relevance to the business | G9: Medium | H9: 4 | I9: Human validation before acting; explainability of the assigned relevance.
A10: 6 | B10: Automatic generation of policies and procedures | C10: Generate internal policies (acceptable use of AI, privacy, security) based on regulatory frameworks. | D10: GenAI | E10: Processing time, alignment with frames, maintenance | F10: Regulatory frameworks, existing policies, business context | G10: Quick Win | H10: 4 | I10: Human approval; validity and updating; traceability of changes.
A11: 7 | B11: Conversational compliance assistant | C11: Answer internal questions about regulations, internal policies and procedures, with citations to the source. | D11: GenAI / RAG | E11: Response time, staff self-sufficiency, FCR | F11: Corpus of policies, internal regulations, internal jurisprudence | G11: Quick Win | H11: 5 | I11: Risk of hallucination; obligation to cite source; escalation to human lawyer.
A12: 8 | B12: E-discovery with automatic classification | C12: Find and classify relevant documents in litigation or internal investigations. | D12: ML / GenAI | E12: e-discovery time, classification accuracy, cost | F12: Business documentary corpus, litigation taxonomy | G12: Medium | H12: 5 | I12: Privacy; attorney-client privilege; traceability.
A13: 9 | B13: Fraud detection and AML/CFT | C13: Detects suspicious patterns in transactions for the prevention of money laundering and terrorist financing. | D13: Classic ML | E13: Cases detected, false positive rate, savings in fines | F13: Transaction history, customer data, sanctions lists | G13: Medium | H13: 5 | I13: Bias; fairness; mandatory explainability; SBS/UIF requirements.
A14: 10 | B14: Communications compliance monitoring | C14: Detects risks in emails, internal chats and calls (sensitive information, inappropriate behavior, conflicts). | D14: ML / GenAI | E14: Cases detected, detection time, accuracy | F14: Corpus of internal communications (with consent) | G14: Medium | H14: 3 | I14: Employee privacy; labor rights; transparency with the team; consult local regulations.
A15: 11 | B15: dynamic risk register | C15: It keeps the risk register updated using internal and external sources. | D15: ML / GenAI | E15: Risk coverage, upgrade opportunity, quality | F15: Internal data, external alerts, risk taxonomy | G15: Medium | H15: 3 | I15: Human validation of severity; traceability of changes.
A16: 12 | B16: Whistleblower with anomaly detection | C16: It prioritizes received reports and detects patterns of misconduct over time. | D16: ML / GenAI | E16: Response time to reports, confirmed cases, completeness | F16: Historical reports, case taxonomy | G16: Medium | H16: 3 | I16: Whistleblower anonymity; bias; follow-up obligation.
A17: 13 | B17: Model cards and self-maintained regulatory documentation | C17: It keeps the technical and regulatory documentation of AI systems in production up to date. | D17: GenAI | E17: Documentary coverage, timeliness, quality | F17: Model metadata, training history, operational metrics | G17: Medium | H17: 3 | I17: Traceability; regulatory audit; alignment with ISO 42001.
A19: SUMMARY OF SELECTIONS
A20: Cases marked "Yes": | B20: =COUNTIF(J5:J17,"Sí") -> 0
A21: Cases marked "Maybe": | B21: =COUNTIF(J5:J17,"Tal vez") -> 0
A22: Total candidates (Yes + Maybe): | B22: =COUNTIF(J5:J17,"Sí")+COUNTIF(J5:J17,"Tal vez") -> 0

Sheet  Questionnaire
A1: Self-assessment questionnaire · Legal and Compliance
A2: Answer each question with a score from 1 to 5. The sheet calculates your pain and readiness score, and issues a recommendation based on the 2×2 matrix.
A4: Scale: | B4: 1 = does not exist / very low · 2 = low · 3 = medium · 4 = high · 5 = systematic / very high
A6: # | B6: Ask | C6: Score (1-5)
A8: BLOCK A — Operational Pain
A9: A1 | B9: The volume of contracts/legal documents that the team manually reviews each month is:
A10: A2 | B10: The time we invest in compliance manuals and regulatory documentation is:
A11: A3 | B11: The current regulatory pressure (audits, inspections, recent sanctions) on our sector is:
A12: A4 | B12: Our error or omission rate in legal/compliance documentation is:
A14: BLOCK B — Data Readiness
A15: B1 | B15: We have an updated digital repository of contracts, policies, and legal documentation:
A16: B2 | B16: The taxonomy/classification of legal documents is defined and applied:
A17: B3 | B17: There is a document management system (DMS) with search and traceability:
A18: B4 | B18: The data is integrated with business systems (CRM, ERP, ticketing):
A20: BLOCK C — Team Readiness
A21: C1 | B21: The General Counsel/legal leadership is open to incorporating AI and sponsors:
A22: C2 | B22: There are legaltech profiles or natural allies on the team:
A23: C3 | B23: Culture tolerates experiments where AI can make mistakes at the beginning:
A24: C4 | B24: The team has successfully completed previous transformation projects:
A26: BLOCK D — Strategic Alignment
A27: D1 | B27: We have explicit goals for legal efficiency, risk reduction, or speed of review:
A28: D2 | B28: There is a reasonable budget to invest in legaltech/AI in the next 12 months:
A29: D3 | B29: Applicable regulations allow us to use AI in legal reviews and proceedings:
A30: D4 | B30: There is a clear business case for impact on costs, risks, or time:
A33: RESULTS
A34: Pain score (Block A): | B34: =IFERROR(AVERAGE(C9:C12),0) -> 0 | C34: =IF(B34=0,"Sin datos",IF(B34>=3.5,"Pain ALTO",IF(B34>=2.5,"Pain MEDIO","Pain BAJO"))) -> No data
A35: Readiness score (Blocks B + C + D): | B35: =IFERROR(AVERAGE(C15:C18,C21:C24,C27:C30),0) -> 0 | C35: =IF(B35=0,"Sin datos",IF(B35>=3.5,"Readiness ALTA",IF(B35>=2.5,"Readiness MEDIA","Readiness BAJA"))) -> No data
A37: RECOMMENDATION: | B37: =IF(OR(B34=0,B35=0),"Completa primero el cuestionario",IF(AND(B34>=3.5,B35>=3.5),"QUICK WIN PRIORITARIO — Avanzar ahora",IF(AND(B34>=3.5,B35<3.5),"INVERTIR EN HABILITADORES — Pain alto pero falta readiness",IF(AND(B34<3.5,B35>=3.5),"OPORTUNIDAD SIN URGENCIA — Capacidad sí, pain no","AÚN NO ES MOMENTO — Construir capacidad antes")))) -> First, complete the questionnaire.
A40: 2×2 Matrix — Pain × Readiness
B41: Readiness LOW (< 3.5) | C41: Readiness HIGH (≥ 3.5)
A42: High Pain (≥ 3.5) | B42: Invest in enablers first | C42: PRIORITY QUICK WIN
A43: LOW Pain (< 3.5) | B43: It's not time yet. | C43: Opportunity without urgency

Sheet  Canvas
A1: Opportunity Canvas · Legal and Compliance
A2: Document a specific opportunity on one page. Replace the italicized text with your information. Output ready to populate the Module 2 template.
A4: 1. Case Name
A5: Prompt: ≤ 8 words
A6: e.g. Internal compliance conversational assistant
A7: 2. Specific pain point
A8: Prompt: Today our legal/compliance team suffers X when Y
A9: For example, today our team receives ~120 internal inquiries per month about regulations and policies, which consumes 60 hours per month of the senior team.
A10: 3. Frequency and volume
A11: Prompt: How many times does this happen per month and who does it affect?
A12: E.g. ~120 queries/month, 4 senior lawyers affected, 250+ internal users consulting.
A13: 4. Estimated cost of pain
... A37: When you complete all 10 fields, copy the content into the Module 2 opportunity template. Field 9 (risks + jurisdiction) should align with the Compliance Radar output for your jurisdiction.

Sheet  Master Table
A1: Master Table of Jurisdictions · Reference Data
A2: Data consolidated as of Q4 2025. Update as regulations change. The Compliance Radar sheet uses this data via VLOOKUP.
A4: Jurisdiction | B4: Region | C4: Main standard | D4: Validity year | E4: Authority | F4: DPIA / PIA required | G4: Explicit consent | H4: Right to explanation | I4: Gap Notification | J4: Mandatory DPO | K4: International transfers | L4: Maximum penalty | M4: EU AI Act extraterritorial | N4: ISO 27001 | O4: ISO 27701 | P4: ISO 42001 | Q4: ISO 23894 | R4: NIST AI RMF | S4: NIST CSF | T4: Local AI framework | U4: Typical sectors | V4: Special notes
A5: Mexico | B5: Latam | C5: LFPDPPP | D5: 2010 (2024 reform in progress) | E5: INAI | F5: Recommended (not explicitly required) | G5: Yes, in most cases | H5: Partial | I5: Immediate (without a specific legal deadline) | J5: Not generally; yes, large volumes. | K5: Permitted with consent or clauses | L5: Up to 320,000 days of minimum wage (~USD 100K-110K) | M5: Yes, if you process EU data or sell to the EU | N5: Highly recommended | O5: Recommended | P5: Recommended | Q5: Recommended | R5: Reference | S5: Reference | T5: Under legislative discussion | U5: CONDUSEF (finance), COFEPRIS (health), CNBV | V5: The 2024 reform brings Mexico closer to international standards. Greater focus on transfers and the rights of the data subject.
A6: Brazil | B6: Latam | C6: LGPD (Law No. 13.709/2018) | D6: 2018 (sanctions from 2021) | E6: ANPD | F6: Yes, RIPD for high risk | G6: Yes (with alternative legal bases) | H6: Yes (Art. 20 - automated decisions) | I6: Within a reasonable timeframe to the ANPD | J6: Yes, mandatory manager | K6: Permitted with standard clauses | L6: 2% of Brazil's previous year's revenue, maximum R$ 50M (~USD 10M) per violation | M6: Yeah | N6: Highly recommended | O6: Recommended | P6: Recommended | Q6: Recommended | R6: Reference | S6: Reference | T6: PL 21/2020 on AI under discussion | U6: BACEN (finance), ANS (health), ANATEL (telecom) | V6: ANPD very active in sanctions since 2023. AI Regulation in legislative progress.
A7: Argentina | B7: Latam | C7: Law 25.326 + Provision 11/2006 | D7: 2000 (reform in progress) | E7: AAIP | F7: Recommended (DIPI - Privacy Impact Document) | G7: Yeah | H7: Partial | I7: Not mandatory (in draft reform) | J7: Not mandatory | K7: Restricted; list of suitable countries | L7: Up to ARS $100,000 per infraction (reform proposes to increase significantly) | M7: Yeah | N7: Highly recommended (BCRA Com. A 7724 requires it of financial institutions) | O7: Recommended | P7: Recommended | Q7: Recommended | R7: Reference | S7: Reference | T7: AI provision under discussion | U7: BCRA (financial institutions), CNV (securities market), SSN (insurance) | V7: Reform of the Personal Data Law under legislative discussion. Central Bank of Argentina (BCRA) very active in cybersecurity.
A8: Chili | B8: Latam | C8: Law 19.628 + Law 21.719 (2024) | D8: 1999 (modernized 2024) | E8: Personal Data Protection Agency (under creation) | F8: Yes, for high risk (post-21.719) | G8: Yes (post-21.719) | H8: Yeah | I8: Yes, 72 hours | J8: Mandatory in some cases | K8: Permitted with clauses | L8: Up to 5,000 UTM (~USD 350K) | M8: Yeah | N8: Highly recommended (CMF requires it of financial institutions) | O8: Recommended | P8: Recommended | Q8: Recommended | R8: Reference | S8: Reference | T8: National AI Policy (2021); AI Bill (2024) | U8: CMF (financial institutions), Superintendency of Health, SUBTEL | V8: Law 21.719 significantly increases requirements and creates the Data Protection Agency. Phased implementation 2024-2026.
A9: Colombia | B9: Latam | C9: Law 1581 + Decree 1377 + Circular 002/2015 | D9: 2012 | E9: SIC (Superintendence of Industry and Commerce) | F9: Yes, PIA (Privacy Impact Assessment) | G9: Yeah | H9: Yeah | I9: Within a reasonable timeframe to the SIC | J9: Recommended | K9: Permitted with consent or clauses | L9: Up to 2,000 SMMLV (~USD 670K) | M9: Yeah | N9: Highly recommended | O9: Recommended | P9: Recommended | Q9: Recommended | R9: Reference | S9: Reference | T9: AI Guidelines issued by the SIC (2024) | U9: SFC (financial institutions), Supersalud, MinTIC | V9: SIC has issued guidelines on AI and published technical guides. It is active in imposing sanctions.
A10: Peru | B10: Latam | C10: Law 29.733 + Regulation (DS 003-2013) | D10: 2011 (Regulations 2013) | E10: ANPD (integrated into MINJUS) | F10: Not explicitly required | G10: Yeah | H10: Partial | I10: Not explicitly required | J10: Not mandatory | K10: Permitted with consent or clauses | L10: Up to 100 UIT (~USD 130K) | M10: Yeah | N10: Recommended | O10: Recommended | P10: Recommended | Q10: Recommended | R10: Reference | S10: Reference | T10: AI regulations under discussion | U10: SBS (financial institutions), SUSALUD, OSIPTEL | V10: Regulatory framework undergoing modernization. Expected modifications aligned with LGPD/GDPR.
A11: Ecuador | B11: Latam | C11: LOPDP (Organic Law on the Protection of Personal Data) | D11: 2021 | E11: SPDP (Superintendency of Personal Data Protection) | F11: Yes, for high risk | G11: Yeah | H11: Yeah | I11: Yes, 5 days | J11: Mandatory in some cases | K11: Permitted with clauses | L11: Up to 0.7% of annual turnover; relevant minimum fines | M11: Yeah | N11: Highly recommended | O11: Recommended | P11: Recommended | Q11: Recommended | R11: Reference | S11: Reference | T11: AI regulations under discussion | U11: Superintendency of Banks, ARCOTEL | V11: LOPDP is very similar to GDPR in structure. SPDP began full operations in 2023.
A12: Uruguay | B12: Latam | C12: Law 18.331 | D12: 2008 | E12: URCDP | F12: Recommended | G12: Yeah | H12: Yeah | I12: Yeah | J12: Recommended | K12: Permitted with suitable countries (EU compliance status) | L12: Up to 500 UR (~USD 25K) | M12: Yeah | N12: Recommended | O12: Recommended | P12: Recommended | Q12: Recommended | R12: Reference | S12: Reference | T12: National AI Strategy (2020) | U12: BCU (financial institutions), URSEC | V12: Uruguay has EU recognition of its compliance. It has a mature framework but with low sanctions in absolute terms.
A13: USA — Federal | B13: USA | C13: No general law; sectoral (HIPAA, GLBA, FCRA, COPPA, FERPA) | D13: It varies by law. | E13: FTC + sector authorities | F13: Sectoral (HIPAA requires Risk Assessment) | G13: Sectorial | H13: Sectorial | I13: Yes, 50 states have breach notification laws | J13: Non-federal | K13: Permitted with sectoral limitations | L13: It varies greatly by sector and violation | M13: Yes, if EU data or system used in the EU | N13: Recommended | O13: Recommended | P13: Recommended | Q13: Recommended | R13: De facto standard | S13: De facto standard | T13: Executive Order on AI (Oct 2023); NIST AI RMF as a voluntary standard | U13: HIPAA (healthcare), GLBA (financial), COPPA (minors), SEC (markets) | V13: No comprehensive federal privacy law. ADPPA under legislative discussion. NIST AI RMF is a must-reference.
A14: USA — California | B14: USA | C14: CCPA + CPRA | D14: 2018 CCPA, 2023 CPRA in force | E14: CPPA (California Privacy Protection Agency) | F14: Yes, for 'high risk processing' under CPRA | G14: Not always (opt-out model); opt-in for sensitive | H14: Limited (opt-out of automated decisions) | I14: Yes (Cal. Civ. Code § 1798.82) | J14: Not mandatory (Privacy Officer recommended) | K14: Not restricted like GDPR | L14: Up to USD 7,500 for intentional violation; USD 2,500 for unintentional violation | M14: Yes, if EU data | N14: Recommended | O14: Recommended | P14: Recommended | Q14: Recommended | R14: De facto standard | S14: De facto standard | T14: CPRA establishes opt-out of automated decision-making | U14: No specific CA sector | V14: Other states with similar laws: Virginia (VCDPA), Colorado (CPA), Connecticut (CTDPA), Utah (UCPA), Texas (TDPSA), etc.
A15: UK | B15: Europe | C15: UK GDPR + Data Protection Act 2018 | D15: 2018 (effective Brexit 2020) | E15: ICO (Information Commissioner's Office) | F15: Yes, mandatory for high risk | G15: Yes, just like GDPR | H15: Yes (Art. 22) | I15: Yes, 72 hours to ICO | J15: Mandatory (similar to GDPR) | K15: Restricted; UK-EU adequacy, IDTA type clauses | L15: £17.5M or 4% of global turnover (whichever is greater) | M15: Not directly; the UK has its own system. | N15: Highly recommended | O15: Recommended | P15: Highly recommended | Q15: Recommended | R15: Reference | S15: Reference | T15: UK AI Regulation White Paper (2023) — sectoral approach | U15: FCA (financial), MHRA (health), Ofcom (communications) | V15: Data Protection and Digital Information Bill under discussion. Pro-innovation regulatory approach with sectoral guidance.
A16: European Union (reference) | B16: Europe | C16: GDPR + EU AI Act | D16: GDPR 2018, EU AI Act 2024 (phased to 2027) | E16: EDPB + national authorities + AI Office | F16: Yes, mandatory for high risk | G16: Yes (with alternative legal bases) | H16: Yes (Art. 22) | I16: Yes, 72 hours | J16: Mandatory in many cases | K16: Restricted; standard clauses, adequacy decisions | L16: GDPR: up to 4% of global turnover. EU AI Act: up to 7% for prohibited systems. | M16: Apply directly | N16: Highly recommended | O16: Highly recommended | P16: De facto standard | Q16: Recommended | R16: Reference | S16: Reference | T16: The EU AI Act classifies systems into 4 risk levels | U16: DORA (financial services), MDR (medical devices) | V16: The EU AI Act has extraterritorial application: it applies to any AI system used in the EU, even if the provider is located outside the EU. Very high fines are imposed.
