Workbook

Sheet Estimador
A1: Estimador de Esfuerzo y Costo
A2: Diagnóstico estratégico de IA · Módulos 1 + 2 + 3 · Versión 1.0
A5: 1. PARÁMETROS DEL CLIENTE
A6: Parámetro | B6: Selección | D6: Factor aplicado
A7: Tamaño del cliente: | B7: Mediana (200-2.000 colaboradores) | D7: =VLOOKUP(B7,Factores!A4:B7,2,FALSE()) -> 1
A8: Sector: | B8: Estándar / no regulado | D8: =VLOOKUP(B8,Factores!D4:E6,2,FALSE()) -> 1
A9: Madurez inicial (M1): | B9: Intermedia (2.5 - 3.4) | D9: =VLOOKUP(B9,Factores!A11:B13,2,FALSE()) -> 1
A10: Geografía: | B10: Single country | D10: =VLOOKUP(B10,Factores!D11:E13,2,FALSE()) -> 1
A11: Assessments previos: | B11: No existen | D11: =VLOOKUP(B11,Factores!A17:B19,2,FALSE()) -> 1
A13: Modo de engagement: | B13: Estándar (M1+M2+M3, 4 semanas) | D13: Cal. base | E13: =VLOOKUP(B13,Factores!D18:H20,5,FALSE()) -> 4 | F13: semanas
A14: Factores por fase (modo): | D14: M1 | E14: =VLOOKUP(B13,Factores!D18:H20,2,FALSE()) -> 1 | F14: M2 | G14: =VLOOKUP(B13,Factores!D18:H20,3,FALSE()) -> 1 | H14: M3 | I14: =VLOOKUP(B13,Factores!D18:H20,4,FALSE()) -> 1
A16: FACTOR DE CLIENTE (combinado): | D16: =D7*D8*D9*D10*D11 -> 1
A18: 2. TARIFAS DEL EQUIPO (USD/día)
A19: Rol | B19: Tarifa USD/día
A20: Sénior / Partner | B20: 2000
A21: Manager / Consultor sr. | B21: 1200
A22: Analista / Consultor | B22: 700
A24: 3. DESGLOSE POR FASE Y ROL
A25: Fase | B25: Sénior días | C25: Manager días | D25: Analista días | E25: Total días | F25: Costo (USD)
A26: Módulo 1 — Fundamentos | B26: =Factores!B24*$D$16*$E$14 -> 5 | C26: =Factores!C24*$D$16*$E$14 -> 5.5 | D26: =Factores!D24*$D$16*$E$14 -> 4 | E26: =SUM(B26:D26) -> 14.5 | F26: =B26*$B$20+C26*$B$21+D26*$B$22 -> 19400
A27: Módulo 2 — Diagnóstico | B27: =Factores!B25*$D$16*$G$14 -> 4.5 | C27: =Factores!C25*$D$16*$G$14 -> 11 | D27: =Factores!D25*$D$16*$G$14 -> 7 | E27: =SUM(B27:D27) -> 22.5 | F27: =B27*$B$20+C27*$B$21+D27*$B$22 -> 27100
A28: Módulo 3 — Portafolio | B28: =Factores!B26*$D$16*$I$14 -> 2.5 | C28: =Factores!C26*$D$16*$I$14 -> 7.5 | D28: =Factores!D26*$D$16*$I$14 -> 6.5 | E28: =SUM(B28:D28) -> 16.5 | F28: =B28*$B$20+C28*$B$21+D28*$B$22 -> 18550
A29: TOTAL | B29: =SUM(B26:B28) -> 12 | C29: =SUM(C26:C28) -> 24 | D29: =SUM(D26:D28) -> 17.5 | E29: =SUM(E26:E28) -> 53.5 | F29: =SUM(F26:F28) -> 65050
A32: 4. RESUMEN EJECUTIVO
A33: Total días-persona: | B33: =E29 -> 53.5
A34: Total horas (8h/día): | B34: =E29*8 -> 428
A35: Calendario sugerido: | B35: =E13" semanas" -> semanas
A36: INVERSIÓN ESTIMADA: | B36: =F29 -> 65050
A39: 5. DESGLOSE POR ROL
A40: Rol | B40: Días totales | C40: del esfuerzo | D40: Horas | E40: Tarifa USD/día | F40: Costo (USD)
A41: Sénior / Partner | B41: =SUM(B26:B28) -> 12 | C41: =B41/$E$29 -> 0.22429907 | D41: =B41*8 -> 96 | E41: =$B$20 -> 2000 | F41: =B41*$B$20 -> 24000
A42: Manager / Consultor sr. | B42: =SUM(C26:C28) -> 24 | C42: =B42/$E$29 -> 0.44859813 | D42: =B42*8 -> 192 | E42: =$B$21 -> 1200 | F42: =B42*$B$21 -> 28800
A43: Analista / Consultor | B43: =SUM(D26:D28) -> 17.5 | C43: =B43/$E$29 -> 0.3271028 | D43: =B43*8 -> 140 | E43: =$B$22 -> 700 | F43: =B43*$B$22 -> 12250
A44: TOTAL | B44: =SUM(B41:B43) -> 53.5 | C44: =SUM(C41:C43) -> 1 | D44: =SUM(D41:D43) -> 428 | F44: =SUM(F41:F43) -> 65050
A47: 6. NOTAS Y SUPUESTOS
A48: • Las tarifas son referenciales para Latinoamérica medio-alto. Ajustar según geografía y estructura del consultor.
A49: • Los días base están calibrados sobre un cliente mediano típico (200-2.000 colaboradores) con madurez intermedia y operación nacional.
A50: • El cálculo asume un día-persona = 8 horas efectivas, descontando reuniones internas y tiempo no facturable.
A51: • Modo Lite: cubre solo Módulo 1 (assessment de madurez + visión estratégica). No incluye diagnóstico por área ni portafolio.
A52: • Modo Estándar: cubre M1 + M2 + M3 en 4 semanas calendario. Es el alcance recomendado para un primer engagement.
...

Sheet Escenarios
A1: Comparación de escenarios
A2: Comparación lado a lado de los tres modos para un cliente típico (mediano, sector estándar, madurez intermedia)
A4: Concepto | B4: Lite | C4: Estándar | D4: Completo
A5: Calendario | B5: semanas | C5: semanas | D5: semanas
A6: Alcance | B6: Solo M1 | C6: M1 + M2 + M3 | D6: M1 + M2 + M3 ampliado
A7: Días sénior | B7: =Factores!B24 -> 5 | C7: =SUM(Factores!B24:B26) -> 12 | D7: =SUM(Factores!B24:B26)*1.2 -> 14.4
A8: Días manager | B8: =Factores!C24 -> 5.5 | C8: =SUM(Factores!C24:C26) -> 24 | D8: =SUM(Factores!C24:C26)*1.2 -> 28.8
A9: Días analista | B9: =Factores!D24 -> 4 | C9: =SUM(Factores!D24:D26) -> 17.5 | D9: =SUM(Factores!D24:D26)*1.2 -> 21
A10: Total días-persona | B10: =B7+B8+B9 -> 14.5 | C10: =C7+C8+C9 -> 53.5 | D10: =D7+D8+D9 -> 64.2
A11: Total horas | B11: =B10*8 -> 116 | C11: =C10*8 -> 428 | D11: =D10*8 -> 513.6
A12: Costo sénior (USD) | B12: =B7*Estimador!$B$20 -> 10000 | C12: =C7*Estimador!$B$20 -> 24000 | D12: =D7*Estimador!$B$20 -> 28800
A13: Costo manager (USD) | B13: =B8*Estimador!$B$21 -> 6600 | C13: =C8*Estimador!$B$21 -> 28800 | D13: =D8*Estimador!$B$21 -> 34560
A14: Costo analista (USD) | B14: =B9*Estimador!$B$22 -> 2800 | C14: =C9*Estimador!$B$22 -> 12250 | D14: =D9*Estimador!$B$22 -> 14700
A15: INVERSIÓN TOTAL | B15: =B12+B13+B14 -> 19400 | C15: =C12+C13+C14 -> 65050 | D15: =D12+D13+D14 -> 78060
A18: Nota: estos cálculos asumen tarifas y días base de la pestaña Estimador (cliente típico, sin factores de ajuste).
A19: Para una estimación parametrizada con factores de tu cliente, usa la pestaña Estimador.

Sheet Factores
A1: Tablas de factores de ajuste
A3: Tamaño del cliente | D3: Sector
A4: Pequeña (<200 colaboradores) | B4: 0.7 | D4: Estándar / no regulado | E4: 1
A5: Mediana (200-2.000 colaboradores) | B5: 1 | D5: Regulado moderado | E5: 1.15
A6: Grande (2.000-10.000 colaboradores) | B6: 1.5 | D6: Altamente regulado (banca/salud/sector público) | E6: 1.3
A7: Multinacional (>10.000 colaboradores) | B7: 2.5
A10: Madurez inicial (M1 score promedio) | D10: Geografía
A11: Inicial (1.0 - 2.4) | B11: 1.1 | D11: Single country | E11: 1
A12: Intermedia (2.5 - 3.4) | B12: 1 | D12: Multi-país (2-3 geografías) | E12: 1.3
A13: Madura (3.5 - 5.0) | B13: 0.9 | D13: Multi-país (4+ geografías) | E13: 1.7
A16: Assessments previos del cliente | D16: Modo de engagement
A17: No existen | B17: 1 | D17: Modo | E17: Factor M1 | F17: Factor M2 | G17: Factor M3 | H17: Calendario base (sem)
A18: Existen parciales | B18: 0.92 | D18: Lite (solo M1, 4 semanas) | E18: 1 | F18: 0 | G18: 0 | H18: 4
A19: Existen completos y vigentes | B19: 0.85 | D19: Estándar (M1+M2+M3, 4 semanas) | E19: 1 | F19: 1 | G19: 1 | H19: 4
D20: Completo (extendido, 6 semanas) | E20: 1.2 | F20: 1.2 | G20: 1.2 | H20: 6
A22: Días base por fase y rol (cliente típico modo estándar)
A23: Fase | B23: Sénior | C23: Manager | D23: Analista | E23: Total
A24: Módulo 1 — Fundamentos | B24: 5 | C24: 5.5 | D24: 4 | E24: =SUM(B24:D24) -> 14.5
A25: Módulo 2 — Diagnóstico | B25: 4.5 | C25: 11 | D25: 7 | E25: =SUM(B25:D25) -> 22.5
A26: Módulo 3 — Portafolio | B26: 2.5 | C26: 7.5 | D26: 6.5 | E26: =SUM(B26:D26) -> 16.5
A27: TOTAL | B27: =SUM(B24:B26) -> 12 | C27: =SUM(C24:C26) -> 24 | D27: =SUM(D24:D26) -> 17.5 | E27: =SUM(E24:E26) -> 53.5
