Workbook

Sheet Compliance Radar
A1: Compliance Radar · IA bajo regulación
A2: Selecciona la jurisdicción de tu cliente y el kit muestra automáticamente las normas aplicables, obligaciones, sanciones y estándares recomendados.
A5: JURISDICCIÓN: | B5: México
A7: Región: | B7: =VLOOKUP($B$5,'Tabla Maestra'!$A$5:$V$16,2,FALSE()) -> Latam
A8: Autoridad de protección de datos: | B8: =VLOOKUP($B$5,'Tabla Maestra'!$A$5:$V$16,5,FALSE()) -> INAI
A10: 1. MARCO LEGAL APLICABLE
A11: Norma principal de protección de datos: | B11: =VLOOKUP($B$5,'Tabla Maestra'!$A$5:$V$16,3,FALSE()) -> LFPDPPP
A12: Año de vigencia: | B12: =VLOOKUP($B$5,'Tabla Maestra'!$A$5:$V$16,4,FALSE()) -> 2010 (reforma 2024 en curso)
A13: EU AI Act extraterritorial: | B13: =VLOOKUP($B$5,'Tabla Maestra'!$A$5:$V$16,13,FALSE()) -> Sí, si trata datos UE o vende a UE
A14: Marco específico de IA (local): | B14: =VLOOKUP($B$5,'Tabla Maestra'!$A$5:$V$16,20,FALSE()) -> En discusión legislativa
A16: 2. OBLIGACIONES CLAVE PARA HACER IA
A17: DPIA / PIA (Evaluación de impacto): | B17: =VLOOKUP($B$5,'Tabla Maestra'!$A$5:$V$16,6,FALSE()) -> Recomendada (no exigida explícitamente)
A18: Consentimiento explícito: | B18: =VLOOKUP($B$5,'Tabla Maestra'!$A$5:$V$16,7,FALSE()) -> Sí, en la mayoría de casos
A19: Derecho a explicación de decisiones automatizadas: | B19: =VLOOKUP($B$5,'Tabla Maestra'!$A$5:$V$16,8,FALSE()) -> Parcial
A20: Notificación de brechas: | B20: =VLOOKUP($B$5,'Tabla Maestra'!$A$5:$V$16,9,FALSE()) -> Inmediata (sin plazo legal específico)
A21: DPO obligatorio: | B21: =VLOOKUP($B$5,'Tabla Maestra'!$A$5:$V$16,10,FALSE()) -> No general; sí grandes volúmenes
A22: Transferencias internacionales: | B22: =VLOOKUP($B$5,'Tabla Maestra'!$A$5:$V$16,11,FALSE()) -> Permitidas con consentimiento o cláusulas
A24: 3. SANCIONES MÁXIMAS
A25: Sanción máxima: | B25: =VLOOKUP($B$5,'Tabla Maestra'!$A$5:$V$16,12,FALSE()) -> Hasta 320,000 días de salario mínimo (~USD 100K-110K)
A27: 4. ESTÁNDARES Y MARCOS RECOMENDADOS
A28: Estándar / Marco | B28: Aplicabilidad | C28: Foco
A29: ISO/IEC 27001 — Information Security | B29: =VLOOKUP($B$5,'Tabla Maestra'!$A$5:$V$16,14,FALSE()) -> Muy recomendado | C29: Seguridad de la información, base de cualquier programa serio.
A30: ISO/IEC 27701 — Privacy Information Management | B30: =VLOOKUP($B$5,'Tabla Maestra'!$A$5:$V$16,15,FALSE()) -> Recomendado | C30: Extensión de 27001 con controles de privacidad. Crítica con datos personales.
A31: ISO/IEC 42001 — AI Management System | B31: =VLOOKUP($B$5,'Tabla Maestra'!$A$5:$V$16,16,FALSE()) -> Recomendado | C31: Sistema de gestión de IA, certificable. Estándar emergente clave.
A32: ISO/IEC 23894 — AI Risk Management | B32: =VLOOKUP($B$5,'Tabla Maestra'!$A$5:$V$16,17,FALSE()) -> Recomendado | C32: Marco operativo de gestión de riesgos en IA.
A33: NIST AI Risk Management Framework | B33: =VLOOKUP($B$5,'Tabla Maestra'!$A$5:$V$16,18,FALSE()) -> Referencia | C33: Marco voluntario de EE.UU. — referencia internacional ampliamente adoptada.
A34: NIST Cybersecurity Framework (CSF) | B34: =VLOOKUP($B$5,'Tabla Maestra'!$A$5:$V$16,19,FALSE()) -> Referencia | C34: Marco de ciberseguridad — estándar de hecho en EE.UU.
A36: 5. SECTORIALES Y NOTAS PARTICULARES
A37: Reguladores sectoriales típicos: | B37: =VLOOKUP($B$5,'Tabla Maestra'!$A$5:$V$16,21,FALSE()) -> CONDUSEF (finanzas), COFEPRIS (salud), CNBV
A38: Notas particulares: | B38: =VLOOKUP($B$5,'Tabla Maestra'!$A$5:$V$16,22,FALSE()) -> Reforma 2024 acerca a México a estándares internacionales. Mayor enfoque en transferencias y derechos del titular.
A41: 6. CHECKLIST OPERATIVO DE COMPLIANCE PARA TU INICIATIVA DE IA
A42: Marca el estado actual de cada control. Sistemas de alto riesgo bajo EU AI Act y muchas normas locales requieren la mayoría de estos controles.
A43: Control | B43: Estado | C43: Comentarios
A44: Inventario actualizado de sistemas de IA en uso o desarrollo
A45: DPIA / PIA realizada para cada sistema con datos personales
A46: Bases legales de tratamiento documentadas
A47: Política de uso aceptable de IA aprobada y comunicada
A48: Model cards o documentación técnica por sistema
A49: Mecanismos de derecho a explicación implementados
A50: Procedimiento de notificación de brechas documentado
...

Sheet Catálogo
A1: Catálogo de casos de uso · IA en Legal y Compliance
A2: Casos de uso de IA aplicables al área legal y compliance. Marca en la última columna los que aplican a tu organización.
A4: # | B4: Caso de uso | C4: Descripción | D4: Familia de IA | E4: KPI típico | F4: Datos requeridos | G4: Esfuerzo | H4: Madurez (1-5) | I4: Compliance / riesgo | J4: ¿Aplica a nosotros? | K4: Notas
A5: 1 | B5: Revisión automática de contratos | C5: Identifica cláusulas de riesgo, desviaciones del estándar, términos faltantes en contratos entrantes. | D5: GenAI | E5: Tiempo de revisión, cobertura de revisión, riesgos detectados | F5: Plantillas maestras, histórico de contratos firmados, criterios de riesgo | G5: Mediano | H5: 5 | I5: Confidencialidad; trazabilidad de versiones; revisión humana obligatoria.
A6: 2 | B6: Generación de borradores de contratos estándar | C6: Auto-genera NDAs, MSAs, SOWs, DPAs a partir de plantillas y parámetros del caso. | D6: GenAI | E6: Tiempo a primer borrador, consistencia, productividad legal | F6: Plantillas maestras, parámetros del caso, datos de la contraparte | G6: Quick Win | H6: 5 | I6: Aprobación humana antes de envío; control de versiones.
A7: 3 | B7: Comparación y redlining de contratos | C7: Compara propuesta de la contraparte con plantilla maestra y sugiere cambios. | D7: GenAI | E7: Tiempo de redlining, riesgos identificados, calidad de cambios | F7: Plantilla maestra, contrato de la contraparte | G7: Quick Win | H7: 4 | I7: Decisión final del abogado; trazabilidad de comentarios.
A8: 4 | B8: DPIA / PIA asistida | C8: Auto-genera borrador de evaluación de impacto en privacidad para iniciativas con datos personales. | D8: GenAI | E8: Tiempo de elaboración de DPIA, completitud, trazabilidad | F8: Descripción del proyecto, datos involucrados, plantilla DPIA | G8: Mediano | H8: 4 | I8: Validación de DPO; revisión humana obligatoria; trazabilidad regulatoria.
A9: 5 | B9: Regulatory change tracking | C9: Monitorea publicaciones oficiales y alerta sobre cambios normativos relevantes para el cliente. | D9: ML / GenAI | E9: Cobertura regulatoria, tiempo de detección, falsos positivos | F9: Fuentes regulatorias oficiales, taxonomía de relevancia para el negocio | G9: Mediano | H9: 4 | I9: Validación humana antes de actuar; explicabilidad de la relevancia asignada.
A10: 6 | B10: Auto-generación de policies y procedimientos | C10: Genera políticas internas (uso aceptable de IA, privacidad, seguridad) a partir de marcos regulatorios. | D10: GenAI | E10: Tiempo de elaboración, alineación con marcos, mantenimiento | F10: Marcos regulatorios, políticas existentes, contexto del negocio | G10: Quick Win | H10: 4 | I10: Aprobación humana; vigencia y actualización; trazabilidad de cambios.
A11: 7 | B11: Asistente conversacional de compliance | C11: Responde preguntas internas sobre normativa, políticas internas y procedimientos, con citas a la fuente. | D11: GenAI / RAG | E11: Tiempo de respuesta, autosuficiencia del personal, FCR | F11: Corpus de políticas, regulación interna, jurisprudencia interna | G11: Quick Win | H11: 5 | I11: Riesgo de alucinación; obligación de citar fuente; escalamiento a abogado humano.
A12: 8 | B12: E-discovery con clasificación automática | C12: Encuentra y clasifica documentos relevantes en litigios o investigaciones internas. | D12: ML / GenAI | E12: Tiempo de e-discovery, precisión de clasificación, costo | F12: Corpus documental empresarial, taxonomía de litigio | G12: Mediano | H12: 5 | I12: Privacy; privilegio abogado-cliente; trazabilidad.
A13: 9 | B13: Detección de fraude y AML / CFT | C13: Detecta patrones sospechosos en transacciones para prevención de lavado y financiamiento del terrorismo. | D13: ML clásico | E13: Casos detectados, tasa de falsos positivos, ahorro en multas | F13: Histórico transaccional, datos del cliente, listas de sanciones | G13: Mediano | H13: 5 | I13: Sesgo; fairness; explicabilidad obligatoria; SBS/UIF requerimientos.
A14: 10 | B14: Compliance monitoring de comunicaciones | C14: Detecta riesgos en emails, chats internos y llamadas (información sensible, conducta inapropiada, conflictos). | D14: ML / GenAI | E14: Casos detectados, tiempo de detección, precisión | F14: Corpus de comunicaciones internas (con consentimiento) | G14: Mediano | H14: 3 | I14: Privacidad de empleados; derechos laborales; transparencia con el equipo; consultar regulación local.
A15: 11 | B15: Risk register dinámico | C15: Mantiene actualizado el registro de riesgos a partir de fuentes internas y externas. | D15: ML / GenAI | E15: Cobertura de riesgos, oportunidad de actualización, calidad | F15: Datos internos, alertas externas, taxonomía de riesgos | G15: Mediano | H15: 3 | I15: Validación humana de severidad; trazabilidad de cambios.
A16: 12 | B16: Whistleblower con detección de anomalías | C16: Prioriza reportes recibidos y detecta patrones de mala conducta a través del tiempo. | D16: ML / GenAI | E16: Tiempo de respuesta a reportes, casos confirmados, completitud | F16: Reportes históricos, taxonomía de casos | G16: Mediano | H16: 3 | I16: Anonimato del denunciante; sesgo; obligación de seguimiento.
A17: 13 | B17: Model cards y documentación regulatoria auto-mantenida | C17: Mantiene actualizada la documentación técnica y regulatoria de los sistemas de IA en producción. | D17: GenAI | E17: Cobertura documental, oportunidad, calidad | F17: Metadata de modelos, históricos de entrenamiento, métricas de operación | G17: Mediano | H17: 3 | I17: Trazabilidad; auditoría regulatoria; alineación con ISO 42001.
A19: RESUMEN DE SELECCIONES
A20: Casos marcados "Sí": | B20: =COUNTIF(J5:J17,"Sí") -> 0
A21: Casos marcados "Tal vez": | B21: =COUNTIF(J5:J17,"Tal vez") -> 0
A22: Total candidatos (Sí + Tal vez): | B22: =COUNTIF(J5:J17,"Sí")+COUNTIF(J5:J17,"Tal vez") -> 0

Sheet Cuestionario
A1: Cuestionario de autoevaluación · Legal y Compliance
A2: Responde cada pregunta con un puntaje de 1 a 5. La hoja calcula tu puntaje de pain y readiness, y emite recomendación según la matriz 2×2.
A4: Escala: | B4: 1 = no existe / muy bajo · 2 = bajo · 3 = medio · 4 = alto · 5 = sistemático / muy alto
A6: # | B6: Pregunta | C6: Puntaje (1-5)
A8: BLOQUE A — Pain operativo
A9: A1 | B9: El volumen de contratos / documentos legales que el equipo revisa manualmente cada mes es:
A10: A2 | B10: El tiempo que invertimos en compliance manual y documentación regulatoria es:
A11: A3 | B11: La presión regulatoria actual (auditorías, fiscalizaciones, sanciones recientes) sobre nuestro sector es:
A12: A4 | B12: Nuestra tasa de errores u omisiones en documentación legal / compliance es:
A14: BLOQUE B — Readiness de datos
A15: B1 | B15: Tenemos repositorio digital actualizado de contratos, políticas y documentación legal:
A16: B2 | B16: La taxonomía/clasificación de documentos legales está definida y se aplica:
A17: B3 | B17: Existe un sistema de gestión documental (DMS) con búsqueda y trazabilidad:
A18: B4 | B18: Los datos están integrados con sistemas de negocio (CRM, ERP, ticketing):
A20: BLOQUE C — Readiness del equipo
A21: C1 | B21: El General Counsel / liderazgo legal está abierto a incorporar IA y patrocina:
A22: C2 | B22: Hay perfiles legaltech o aliados naturales en el equipo:
A23: C3 | B23: La cultura tolera experimentos donde la IA puede equivocarse al inicio:
A24: C4 | B24: El equipo ha pasado por proyectos de transformación previos con éxito razonable:
A26: BLOQUE D — Alineación estratégica
A27: D1 | B27: Tenemos metas explícitas de eficiencia legal, reducción de riesgo o velocidad de revisión:
A28: D2 | B28: Hay presupuesto razonable para invertir en legaltech / IA en los próximos 12 meses:
A29: D3 | B29: La regulación aplicable nos permite usar IA en revisión y procedimientos legales:
A30: D4 | B30: Existe un caso de negocio claro de impacto en costos, riesgos o tiempo:
A33: RESULTADOS
A34: Pain score (Bloque A): | B34: =IFERROR(AVERAGE(C9:C12),0) -> 0 | C34: =IF(B34=0,"Sin datos",IF(B34>=3.5,"Pain ALTO",IF(B34>=2.5,"Pain MEDIO","Pain BAJO"))) -> Sin datos
A35: Readiness score (Bloques B + C + D): | B35: =IFERROR(AVERAGE(C15:C18,C21:C24,C27:C30),0) -> 0 | C35: =IF(B35=0,"Sin datos",IF(B35>=3.5,"Readiness ALTA",IF(B35>=2.5,"Readiness MEDIA","Readiness BAJA"))) -> Sin datos
A37: RECOMENDACIÓN: | B37: =IF(OR(B34=0,B35=0),"Completa primero el cuestionario",IF(AND(B34>=3.5,B35>=3.5),"QUICK WIN PRIORITARIO — Avanzar ahora",IF(AND(B34>=3.5,B35<3.5),"INVERTIR EN HABILITADORES — Pain alto pero falta readiness",IF(AND(B34<3.5,B35>=3.5),"OPORTUNIDAD SIN URGENCIA — Capacidad sí, pain no","AÚN NO ES MOMENTO — Construir capacidad antes")))) -> Completa primero el cuestionario
A40: Matriz 2×2 — Pain × Readiness
B41: Readiness BAJA (< 3.5) | C41: Readiness ALTA (≥ 3.5)
A42: Pain ALTO (≥ 3.5) | B42: Invertir en habilitadores primero | C42: QUICK WIN PRIORITARIO
A43: Pain BAJO (< 3.5) | B43: Aún no es momento | C43: Oportunidad sin urgencia

Sheet Canvas
A1: Canvas de oportunidad · Legal y Compliance
A2: Documenta una oportunidad concreta en una página. Reemplaza el texto en cursiva con tu información. Salida lista para alimentar la plantilla del Módulo 2.
A4: 1. Nombre del caso
A5: Prompt: ≤ 8 palabras
A6: Ej. Asistente conversacional de compliance interno
A7: 2. Pain point concreto
A8: Prompt: Hoy nuestro equipo legal/compliance sufre X cuando Y
A9: Ej. Hoy nuestro equipo recibe ~120 consultas internas mensuales sobre normativa y políticas, lo que consume 60 horas mensuales del team senior.
A10: 3. Frecuencia y volumen
A11: Prompt: ¿Cuántas veces ocurre por mes y a quién afecta?
A12: Ej. ~120 consultas/mes, 4 abogados senior afectados, 250+ usuarios internos consultantes.
A13: 4. Costo estimado del dolor
... A37: Cuando completes los 10 campos, copia el contenido en la plantilla de oportunidad del Módulo 2. El campo 9 (riesgos + jurisdicción) debe alinearse con la salida del Compliance Radar para tu jurisdicción.

Sheet Tabla Maestra
A1: Tabla Maestra de Jurisdicciones · Datos de referencia
A2: Datos consolidados a Q4 2025. Actualizar conforme cambien las regulaciones. La hoja Compliance Radar consume estos datos vía VLOOKUP.
A4: Jurisdicción | B4: Región | C4: Norma principal | D4: Año vigencia | E4: Autoridad | F4: DPIA / PIA exigible | G4: Consentimiento explícito | H4: Derecho a explicación | I4: Notificación de brechas | J4: DPO obligatorio | K4: Transferencias internacionales | L4: Sanción máxima | M4: EU AI Act extraterritorial | N4: ISO 27001 | O4: ISO 27701 | P4: ISO 42001 | Q4: ISO 23894 | R4: NIST AI RMF | S4: NIST CSF | T4: Marco IA local | U4: Sectoriales típicas | V4: Notas particulares
A5: México | B5: Latam | C5: LFPDPPP | D5: 2010 (reforma 2024 en curso) | E5: INAI | F5: Recomendada (no exigida explícitamente) | G5: Sí, en la mayoría de casos | H5: Parcial | I5: Inmediata (sin plazo legal específico) | J5: No general; sí grandes volúmenes | K5: Permitidas con consentimiento o cláusulas | L5: Hasta 320,000 días de salario mínimo (~USD 100K-110K) | M5: Sí, si trata datos UE o vende a UE | N5: Muy recomendado | O5: Recomendado | P5: Recomendado | Q5: Recomendado | R5: Referencia | S5: Referencia | T5: En discusión legislativa | U5: CONDUSEF (finanzas), COFEPRIS (salud), CNBV | V5: Reforma 2024 acerca a México a estándares internacionales. Mayor enfoque en transferencias y derechos del titular.
A6: Brasil | B6: Latam | C6: LGPD (Lei nº 13.709/2018) | D6: 2018 (sanciones desde 2021) | E6: ANPD | F6: Sí, RIPD para alto riesgo | G6: Sí (con bases legales alternativas) | H6: Sí (Art. 20 - decisiones automatizadas) | I6: En plazo razonable a la ANPD | J6: Sí, encargado obligatorio | K6: Permitidas con cláusulas estándar | L6: 2% facturación Brasil año anterior, máximo R$ 50M (~USD 10M) por infracción | M6: Sí | N6: Muy recomendado | O6: Recomendado | P6: Recomendado | Q6: Recomendado | R6: Referencia | S6: Referencia | T6: PL 21/2020 sobre IA en discusión | U6: BACEN (finanzas), ANS (salud), ANATEL (telecom) | V6: ANPD muy activa en sanciones desde 2023. Reglamento de IA en avance legislativo.
A7: Argentina | B7: Latam | C7: Ley 25.326 + Disp. 11/2006 | D7: 2000 (reforma en curso) | E7: AAIP | F7: Recomendada (DIPI - Documento de Impacto en la Privacidad) | G7: Sí | H7: Parcial | I7: No obligatorio (en proyecto de reforma) | J7: No obligatorio | K7: Restringidas; lista de países adecuados | L7: Hasta $100,000 ARS por infracción (reforma propone aumentar significativamente) | M7: Sí | N7: Muy recomendado (BCRA Com. A 7724 lo exige a financieras) | O7: Recomendado | P7: Recomendado | Q7: Recomendado | R7: Referencia | S7: Referencia | T7: Disposición sobre IA en discusión | U7: BCRA (financieras), CNV (mercado de valores), SSN (seguros) | V7: Reforma de la Ley de Datos Personales en discusión legislativa. BCRA muy activa en ciberseguridad.
A8: Chile | B8: Latam | C8: Ley 19.628 + Ley 21.719 (2024) | D8: 1999 (modernizada 2024) | E8: Agencia de Protección de Datos Personales (en creación) | F8: Sí, para alto riesgo (post-21.719) | G8: Sí (post-21.719) | H8: Sí | I8: Sí, 72 horas | J8: Obligatorio en algunos casos | K8: Permitidas con cláusulas | L8: Hasta 5,000 UTM (~USD 350K) | M8: Sí | N8: Muy recomendado (CMF lo exige a financieras) | O8: Recomendado | P8: Recomendado | Q8: Recomendado | R8: Referencia | S8: Referencia | T8: Política Nacional de IA (2021); Proyecto de Ley de IA (2024) | U8: CMF (financieras), Superintendencia de Salud, SUBTEL | V8: Ley 21.719 incrementa significativamente las exigencias y crea la Agencia de Protección de Datos. Vigencia escalonada 2024-2026.
A9: Colombia | B9: Latam | C9: Ley 1581 + Decreto 1377 + Circular 002/2015 | D9: 2012 | E9: SIC (Superintendencia de Industria y Comercio) | F9: Sí, PIA (Procedimiento de Impacto en la Privacidad) | G9: Sí | H9: Sí | I9: En plazo razonable a la SIC | J9: Recomendado | K9: Permitidas con consentimiento o cláusulas | L9: Hasta 2,000 SMMLV (~USD 670K) | M9: Sí | N9: Muy recomendado | O9: Recomendado | P9: Recomendado | Q9: Recomendado | R9: Referencia | S9: Referencia | T9: Lineamientos sobre IA emitidos por la SIC (2024) | U9: SFC (financieras), Supersalud, MinTIC | V9: SIC ha emitido lineamientos sobre IA y publicado guías técnicas. Activa en sanciones.
A10: Perú | B10: Latam | C10: Ley 29.733 + Reglamento (D.S. 003-2013) | D10: 2011 (Reglamento 2013) | E10: ANPD (integrada en MINJUS) | F10: No obligatoria explícitamente | G10: Sí | H10: Parcial | I10: No obligatorio explícitamente | J10: No obligatorio | K10: Permitidas con consentimiento o cláusulas | L10: Hasta 100 UIT (~USD 130K) | M10: Sí | N10: Recomendado | O10: Recomendado | P10: Recomendado | Q10: Recomendado | R10: Referencia | S10: Referencia | T10: Reglamento de IA en discusión | U10: SBS (financieras), SUSALUD, OSIPTEL | V10: Marco regulatorio en proceso de modernización. Modificaciones esperadas alineadas con LGPD/GDPR.
A11: Ecuador | B11: Latam | C11: LOPDP (Ley Orgánica de Protección de Datos Personales) | D11: 2021 | E11: SPDP (Superintendencia de Protección de Datos Personales) | F11: Sí, para alto riesgo | G11: Sí | H11: Sí | I11: Sí, 5 días | J11: Obligatorio en algunos casos | K11: Permitidas con cláusulas | L11: Hasta 0.7% facturación anual; multas mínimas relevantes | M11: Sí | N11: Muy recomendado | O11: Recomendado | P11: Recomendado | Q11: Recomendado | R11: Referencia | S11: Referencia | T11: Reglamento de IA en discusión | U11: Superintendencia de Bancos, ARCOTEL | V11: LOPDP es muy similar a GDPR en estructura. SPDP comenzó operaciones plenas en 2023.
A12: Uruguay | B12: Latam | C12: Ley 18.331 | D12: 2008 | E12: URCDP | F12: Recomendada | G12: Sí | H12: Sí | I12: Sí | J12: Recomendado | K12: Permitidas con países adecuados (status de adecuación con UE) | L12: Hasta 500 UR (~USD 25K) | M12: Sí | N12: Recomendado | O12: Recomendado | P12: Recomendado | Q12: Recomendado | R12: Referencia | S12: Referencia | T12: Estrategia Nacional de IA (2020) | U12: BCU (financieras), URSEC | V12: Uruguay tiene reconocimiento de adecuación de la UE. Marco maduro pero con sanciones bajas en términos absolutos.
A13: USA — Federal | B13: USA | C13: Sin ley general; sectoral (HIPAA, GLBA, FCRA, COPPA, FERPA) | D13: Varía por ley | E13: FTC + autoridades sectoriales | F13: Sectorial (HIPAA exige Risk Assessment) | G13: Sectorial | H13: Sectorial | I13: Sí, 50 estados con leyes de notificación de brechas | J13: No federal | K13: Permitidas con limitaciones sectoriales | L13: Varía mucho por sector y violación | M13: Sí, si datos UE o sistema usado en UE | N13: Recomendado | O13: Recomendado | P13: Recomendado | Q13: Recomendado | R13: Estándar de facto | S13: Estándar de facto | T13: Executive Order on AI (Oct 2023); NIST AI RMF como estándar voluntario | U13: HIPAA (salud), GLBA (financieras), COPPA (menores), SEC (mercados) | V13: Sin ley federal de privacidad general. ADPPA en discusión legislativa. NIST AI RMF es referencia obligada.
A14: USA — California | B14: USA | C14: CCPA + CPRA | D14: 2018 CCPA, 2023 CPRA vigente | E14: CPPA (California Privacy Protection Agency) | F14: Sí, para 'high risk processing' bajo CPRA | G14: No siempre (opt-out model); opt-in para sensibles | H14: Limitado (opt-out de decisiones automatizadas) | I14: Sí (Cal. Civ. Code § 1798.82) | J14: No obligatorio (Privacy Officer recomendado) | K14: No restringidas como GDPR | L14: Hasta USD 7,500 por violación intencional; USD 2,500 por no intencional | M14: Sí, si datos UE | N14: Recomendado | O14: Recomendado | P14: Recomendado | Q14: Recomendado | R14: Estándar de facto | S14: Estándar de facto | T14: CPRA establece opt-out de automated decision-making | U14: Ninguna sectorial específica de CA | V14: Otros estados con leyes similares: Virginia (VCDPA), Colorado (CPA), Connecticut (CTDPA), Utah (UCPA), Texas (TDPSA), etc.
A15: UK | B15: Europa | C15: UK GDPR + Data Protection Act 2018 | D15: 2018 (efectivo Brexit 2020) | E15: ICO (Information Commissioner's Office) | F15: Sí, obligatorio para alto riesgo | G15: Sí, igual que GDPR | H15: Sí (Art. 22) | I15: Sí, 72 horas a ICO | J15: Obligatorio (similar GDPR) | K15: Restringidas; UK-EU adecuación, cláusulas tipo IDTA | L15: £17.5M o 4% facturación global (lo mayor) | M15: No directamente; UK con régimen propio | N15: Muy recomendado | O15: Recomendado | P15: Muy recomendado | Q15: Recomendado | R15: Referencia | S15: Referencia | T15: UK AI Regulation White Paper (2023) — enfoque sectorial | U15: FCA (financieras), MHRA (salud), Ofcom (comunicaciones) | V15: Data Protection and Digital Information Bill en discusión. Enfoque regulatorio pro-innovación con guidance sectorial.
A16: Unión Europea (referencia) | B16: Europa | C16: GDPR + EU AI Act | D16: GDPR 2018, EU AI Act 2024 (escalonado a 2027) | E16: EDPB + autoridades nacionales + AI Office | F16: Sí, obligatorio para alto riesgo | G16: Sí (con bases legales alternativas) | H16: Sí (Art. 22) | I16: Sí, 72 horas | J16: Obligatorio en muchos casos | K16: Restringidas; cláusulas tipo, decisiones de adecuación | L16: GDPR: hasta 4% facturación global. EU AI Act: hasta 7% para sistemas prohibidos | M16: Aplica directamente | N16: Muy recomendado | O16: Muy recomendado | P16: Estándar de facto | Q16: Recomendado | R16: Referencia | S16: Referencia | T16: EU AI Act clasifica sistemas en 4 niveles de riesgo | U16: DORA (servicios financieros), MDR (dispositivos médicos) | V16: EU AI Act tiene aplicación extraterritorial: aplica a cualquier sistema de IA usado en la UE, incluso si el proveedor está fuera. Multas muy elevadas.
